Workbook

Sheet Dashboard
A1: 🏨 Fairfield Maintenance Command Center
A2: Real-time operations dashboard · Work Orders · PM Schedules · Parts Inventory · Facility Health
A4: 🎟️ Open Tickets | B4: =COUNTIF('Active Work Orders'!G4:G251,"Not Started")+COUNTIF('Active Work Orders'!G4:G251,"Work In Progress") -> 33 | D4: Work Order Status | G4: Open WOs by Priority
A5: 🏠 Rooms w/ Open WOs | B5: =IFERROR(__xludf.DUMMYFUNCTION("IFERROR(COUNTUNIQUE(FILTER('Active Work Orders'!B4:B251,'Active Work Orders'!A4:A251<>"""",'Active Work Orders'!B4:B251<>"""",'Active Work Orders'!B4:B251<>""Other"",'Active Work Orders'!G4:G251<>""Completed"")),0)"),20.0) -> 20 | D5: Not Started | E5: =COUNTIF('Active Work Orders'!G4:G251,"Not Started") -> 29 | G5: 🚨 Critical | H5: =COUNTIF('Active Work Orders'!E4:E251,"Critical") -> 28
A6: ⚠️ PMs Overdue | B6: =COUNTIF('Room Inspections'!N4:N250,"Overdue") -> 0 | D6: Work In Progress | E6: =COUNTIF('Active Work Orders'!G4:G251,"Work In Progress") -> 4 | G6: 🔴 High | H6: =COUNTIF('Active Work Orders'!E4:E251,"High") -> 29
A7: 📦 Parts to Reorder | B7: =COUNTIF('Parts Inventory'!K4:K250,"Reorder") -> 0 | D7: Completed | E7: =COUNTIF('Active Work Orders'!G4:G251,"Completed") -> 63 | G7: 🟡 Medium | H7: =COUNTIF('Active Work Orders'!E4:E251,"Medium") -> 19
G8: 🟢 Low | H8: =COUNTIF('Active Work Orders'!E4:E251,"Low") -> 21
A10: 🚨 Critical & High Priority Open Work Orders | J10: 🔔 Upcoming PM — Due Within 7 Days
A11: Room / Location | B11: Issue Type | C11: Priority | J11: Room / Space | K11: Performed By | L11: Last PM Date | M11: Next Due Date | N11: Days Remaining | O11: PM Status
A12: =IFERROR(__xludf.DUMMYFUNCTION("IFERROR(INDEX(SORT(FILTER('Active Work Orders'!B4:G251,('Active Work Orders'!E4:E251=""Critical"")+('Active Work Orders'!E4:E251=""High""),'Active Work Orders'!G4:G251<>""Completed"",'Active Work Orders'!B4:B251<>""""),4,TRUE),1,1),"""")"),201.0) -> 201 | B12: =IFERROR(__xludf.DUMMYFUNCTION("IF(A12="""","""",IFERROR(INDEX(SORT(FILTER('Active Work Orders'!B4:G251,('Active Work Orders'!E4:E251=""Critical"")+('Active Work Orders'!E4:E251=""High""),'Active Work Orders'!G4:G251<>""Completed"",'Active Work Orders'!B4:B251<>""""),4,TRUE),1,2),""""))"),"Electrical") -> Electrical | C12: =IFERROR(__xludf.DUMMYFUNCTION("IF(A12="""","""",IFERROR(INDEX(SORT(FILTER('Active Work Orders'!B4:G251,('Active Work Orders'!E4:E251=""Critical"")+('Active Work Orders'!E4:E251=""High""),'Active Work Orders'!G4:G251<>""Completed"",'Active Work Orders'!B4:B251<>""""),4,TRUE),1,4),""""))"),"Critical") -> Critical | J12: =IFERROR(__xludf.DUMMYFUNCTION("IFERROR(INDEX(SORT(FILTER('Room Inspections'!B4:N250,'Room Inspections'!K4:K250<>"""",'Room Inspections'!M4:M250<=7),12,TRUE),1,1),"""")"),"") | K12: =IFERROR(__xludf.DUMMYFUNCTION("IF(J12="""","""",INDEX(SORT(FILTER('Room Inspections'!B4:N250,'Room Inspections'!K4:K250<>"""",'Room Inspections'!M4:M250<=7),12,TRUE),1,9))"),"") | L12: =IFERROR(__xludf.DUMMYFUNCTION("IF(J12="""","""",INDEX(SORT(FILTER('Room Inspections'!B4:N250,'Room Inspections'!K4:K250<>"""",'Room Inspections'!M4:M250<=7),12,TRUE),1,10))"),"") | M12: =IFERROR(__xludf.DUMMYFUNCTION("IF(J12="""","""",INDEX(SORT(FILTER('Room Inspections'!B4:N250,'Room Inspections'!K4:K250<>"""",'Room Inspections'!M4:M250<=7),12,TRUE),1,11))"),"") | N12: =IFERROR(__xludf.DUMMYFUNCTION("IF(J12="""","""",INDEX(SORT(FILTER('Room Inspections'!B4:N250,'Room Inspections'!K4:K250<>"""",'Room Inspections'!M4:M250<=7),12,TRUE),1,12))"),"") | O12: =IFERROR(__xludf.DUMMYFUNCTION("IF(J12="""","""",INDEX(SORT(FILTER('Room Inspections'!B4:N250,'Room Inspections'!K4:K250<>"""",'Room Inspections'!M4:M250<=7),12,TRUE),1,13))"),"")
A13: =IFERROR(__xludf.DUMMYFUNCTION("IFERROR(INDEX(SORT(FILTER('Active Work Orders'!B4:G251,('Active Work Orders'!E4:E251=""Critical"")+('Active Work Orders'!E4:E251=""High""),'Active Work Orders'!G4:G251<>""Completed"",'Active Work Orders'!B4:B251<>""""),4,TRUE),2,1),"""")"),209.0) -> 209 | B13: =IFERROR(__xludf.DUMMYFUNCTION("IF(A13="""","""",IFERROR(INDEX(SORT(FILTER('Active Work Orders'!B4:G251,('Active Work Orders'!E4:E251=""Critical"")+('Active Work Orders'!E4:E251=""High""),'Active Work Orders'!G4:G251<>""Completed"",'Active Work Orders'!B4:B251<>""""),4,TRUE),2,2),""""))"),"Doors") -> Doors | C13: =IFERROR(__xludf.DUMMYFUNCTION("IF(A13="""","""",IFERROR(INDEX(SORT(FILTER('Active Work Orders'!B4:G251,('Active Work Orders'!E4:E251=""Critical"")+('Active Work Orders'!E4:E251=""High""),'Active Work Orders'!G4:G251<>""Completed"",'Active Work Orders'!B4:B251<>""""),4,TRUE),2,4),""""))"),"Critical") -> Critical | J13: =IFERROR(__xludf.DUMMYFUNCTION("IFERROR(INDEX(SORT(FILTER('Room Inspections'!B4:N250,'Room Inspections'!K4:K250<>"""",'Room Inspections'!M4:M250<=7),12,TRUE),2,1),"""")"),"") | K13: =IFERROR(__xludf.DUMMYFUNCTION("IF(J13="""","""",INDEX(SORT(FILTER('Room Inspections'!B4:N250,'Room Inspections'!K4:K250<>"""",'Room Inspections'!M4:M250<=7),12,TRUE),2,9))"),"") | L13: =IFERROR(__xludf.DUMMYFUNCTION("IF(J13="""","""",INDEX(SORT(FILTER('Room Inspections'!B4:N250,'Room Inspections'!K4:K250<>"""",'Room Inspections'!M4:M250<=7),12,TRUE),2,10))"),"") | M13: =IFERROR(__xludf.DUMMYFUNCTION("IF(J13="""","""",INDEX(SORT(FILTER('Room Inspections'!B4:N250,'Room Inspections'!K4:K250<>"""",'Room Inspections'!M4:M250<=7),12,TRUE),2,11))"),"") | N13: =IFERROR(__xludf.DUMMYFUNCTION("IF(J13="""","""",INDEX(SORT(FILTER('Room Inspections'!B4:N250,'Room Inspections'!K4:K250<>"""",'Room Inspections'!M4:M250<=7),12,TRUE),2,12))"),"") | O13: =IFERROR(__xludf.DUMMYFUNCTION("IF(J13="""","""",INDEX(SORT(FILTER('Room Inspections'!B4:N250,'Room Inspections'!K4:K250<>"""",'Room Inspections'!M4:M250<=7),12,TRUE),2,13))"),"")
A14: =IFERROR(__xludf.DUMMYFUNCTION("IFERROR(INDEX(SORT(FILTER('Active Work Orders'!B4:G251,('Active Work Orders'!E4:E251=""Critical"")+('Active Work Orders'!E4:E251=""High""),'Active Work Orders'!G4:G251<>""Completed"",'Active Work Orders'!B4:B251<>""""),4,TRUE),3,1),"""")"),219.0) -> 219 | B14: =IFERROR(__xludf.DUMMYFUNCTION("IF(A14="""","""",IFERROR(INDEX(SORT(FILTER('Active Work Orders'!B4:G251,('Active Work Orders'!E4:E251=""Critical"")+('Active Work Orders'!E4:E251=""High""),'Active Work Orders'!G4:G251<>""Completed"",'Active Work Orders'!B4:B251<>""""),4,TRUE),3,2),""""))"),"Doors") -> Doors | C14: =IFERROR(__xludf.DUMMYFUNCTION("IF(A14="""","""",IFERROR(INDEX(SORT(FILTER('Active Work Orders'!B4:G251,('Active Work Orders'!E4:E251=""Critical"")+('Active Work Orders'!E4:E251=""High""),'Active Work Orders'!G4:G251<>""Completed"",'Active Work Orders'!B4:B251<>""""),4,TRUE),3,4),""""))"),"Critical") -> Critical | J14: =IFERROR(__xludf.DUMMYFUNCTION("IFERROR(INDEX(SORT(FILTER('Room Inspections'!B4:N250,'Room Inspections'!K4:K250<>"""",'Room Inspections'!M4:M250<=7),12,TRUE),3,1),"""")"),"") | K14: =IFERROR(__xludf.DUMMYFUNCTION("IF(J14="""","""",INDEX(SORT(FILTER('Room Inspections'!B4:N250,'Room Inspections'!K4:K250<>"""",'Room Inspections'!M4:M250<=7),12,TRUE),3,9))"),"") | L14: =IFERROR(__xludf.DUMMYFUNCTION("IF(J14="""","""",INDEX(SORT(FILTER('Room Inspections'!B4:N250,'Room Inspections'!K4:K250<>"""",'Room Inspections'!M4:M250<=7),12,TRUE),3,10))"),"") | M14: =IFERROR(__xludf.DUMMYFUNCTION("IF(J14="""","""",INDEX(SORT(FILTER('Room Inspections'!B4:N250,'Room Inspections'!K4:K250<>"""",'Room Inspections'!M4:M250<=7),12,TRUE),3,11))"),"") | N14: =IFERROR(__xludf.DUMMYFUNCTION("IF(J14="""","""",INDEX(SORT(FILTER('Room Inspections'!B4:N250,'Room Inspections'!K4:K250<>"""",'Room Inspections'!M4:M250<=7),12,TRUE),3,12))"),"") | O14: =IFERROR(__xludf.DUMMYFUNCTION("IF(J14="""","""",INDEX(SORT(FILTER('Room Inspections'!B4:N250,'Room Inspections'!K4:K250<>"""",'Room Inspections'!M4:M250<=7),12,TRUE),3,13))"),"")
A15: =IFERROR(__xludf.DUMMYFUNCTION("IFERROR(INDEX(SORT(FILTER('Active Work Orders'!B4:G251,('Active Work Orders'!E4:E251=""Critical"")+('Active Work Orders'!E4:E251=""High""),'Active Work Orders'!G4:G251<>""Completed"",'Active Work Orders'!B4:B251<>""""),4,TRUE),4,1),"""")"),303.0) -> 303 | B15: =IFERROR(__xludf.DUMMYFUNCTION("IF(A15="""","""",IFERROR(INDEX(SORT(FILTER('Active Work Orders'!B4:G251,('Active Work Orders'!E4:E251=""Critical"")+('Active Work Orders'!E4:E251=""High""),'Active Work Orders'!G4:G251<>""Completed"",'Active Work Orders'!B4:B251<>""""),4,TRUE),4,2),""""))"),"Doors") -> Doors | C15: =IFERROR(__xludf.DUMMYFUNCTION("IF(A15="""","""",IFERROR(INDEX(SORT(FILTER('Active Work Orders'!B4:G251,('Active Work Orders'!E4:E251=""Critical"")+('Active Work Orders'!E4:E251=""High""),'Active Work Orders'!G4:G251<>""Completed"",'Active Work Orders'!B4:B251<>""""),4,TRUE),4,4),""""))"),"Critical") -> Critical | J15: =IFERROR(__xludf.DUMMYFUNCTION("IFERROR(INDEX(SORT(FILTER('Room Inspections'!B4:N250,'Room Inspections'!K4:K250<>"""",'Room Inspections'!M4:M250<=7),12,TRUE),4,1),"""")"),"") | K15: =IFERROR(__xludf.DUMMYFUNCTION("IF(J15="""","""",INDEX(SORT(FILTER('Room Inspections'!B4:N250,'Room Inspections'!K4:K250<>"""",'Room Inspections'!M4:M250<=7),12,TRUE),4,9))"),"") | L15: =IFERROR(__xludf.DUMMYFUNCTION("IF(J15="""","""",INDEX(SORT(FILTER('Room Inspections'!B4:N250,'Room Inspections'!K4:K250<>"""",'Room Inspections'!M4:M250<=7),12,TRUE),4,10))"),"") | M15: =IFERROR(__xludf.DUMMYFUNCTION("IF(J15="""","""",INDEX(SORT(FILTER('Room Inspections'!B4:N250,'Room Inspections'!K4:K250<>"""",'Room Inspections'!M4:M250<=7),12,TRUE),4,11))"),"") | N15: =IFERROR(__xludf.DUMMYFUNCTION("IF(J15="""","""",INDEX(SORT(FILTER('Room Inspections'!B4:N250,'Room Inspections'!K4:K250<>"""",'Room Inspections'!M4:M250<=7),12,TRUE),4,12))"),"") | O15: =IFERROR(__xludf.DUMMYFUNCTION("IF(J15="""","""",INDEX(SORT(FILTER('Room Inspections'!B4:N250,'Room Inspections'!K4:K250<>"""",'Room Inspections'!M4:M250<=7),12,TRUE),4,13))"),"")
A16: =IFERROR(__xludf.DUMMYFUNCTION("IFERROR(INDEX(SORT(FILTER('Active Work Orders'!B4:G251,('Active Work Orders'!E4:E251=""Critical"")+('Active Work Orders'!E4:E251=""High""),'Active Work Orders'!G4:G251<>""Completed"",'Active Work Orders'!B4:B251<>""""),4,TRUE),5,1),"""")"),304.0) -> 304 | B16: =IFERROR(__xludf.DUMMYFUNCTION("IF(A16="""","""",IFERROR(INDEX(SORT(FILTER('Active Work Orders'!B4:G251,('Active Work Orders'!E4:E251=""Critical"")+('Active Work Orders'!E4:E251=""High""),'Active Work Orders'!G4:G251<>""Completed"",'Active Work Orders'!B4:B251<>""""),4,TRUE),5,2),""""))"),"Safety") -> Safety | C16: =IFERROR(__xludf.DUMMYFUNCTION("IF(A16="""","""",IFERROR(INDEX(SORT(FILTER('Active Work Orders'!B4:G251,('Active Work Orders'!E4:E251=""Critical"")+('Active Work Orders'!E4:E251=""High""),'Active Work Orders'!G4:G251<>""Completed"",'Active Work Orders'!B4:B251<>""""),4,TRUE),5,4),""""))"),"Critical") -> Critical | J16: =IFERROR(__xludf.DUMMYFUNCTION("IFERROR(INDEX(SORT(FILTER('Room Inspections'!B4:N250,'Room Inspections'!K4:K250<>"""",'Room Inspections'!M4:M250<=7),12,TRUE),5,1),"""")"),"") | K16: =IFERROR(__xludf.DUMMYFUNCTION("IF(J16="""","""",INDEX(SORT(FILTER('Room Inspections'!B4:N250,'Room Inspections'!K4:K250<>"""",'Room Inspections'!M4:M250<=7),12,TRUE),5,9))"),"") | L16: =IFERROR(__xludf.DUMMYFUNCTION("IF(J16="""","""",INDEX(SORT(FILTER('Room Inspections'!B4:N250,'Room Inspections'!K4:K250<>"""",'Room Inspections'!M4:M250<=7),12,TRUE),5,10))"),"") | M16: =IFERROR(__xludf.DUMMYFUNCTION("IF(J16="""","""",INDEX(SORT(FILTER('Room Inspections'!B4:N250,'Room Inspections'!K4:K250<>"""",'Room Inspections'!M4:M250<=7),12,TRUE),5,11))"),"") | N16: =IFERROR(__xludf.DUMMYFUNCTION("IF(J16="""","""",INDEX(SORT(FILTER('Room Inspections'!B4:N250,'Room Inspections'!K4:K250<>"""",'Room Inspections'!M4:M250<=7),12,TRUE),5,12))"),"") | O16: =IFERROR(__xludf.DUMMYFUNCTION("IF(J16="""","""",INDEX(SORT(FILTER('Room Inspections'!B4:N250,'Room Inspections'!K4:K250<>"""",'Room Inspections'!M4:M250<=7),12,TRUE),5,13))"),"")
A19: Work Orders – Last 30 Days by Issue Type
A20: Issue Type | B20: Count
A21: Misc. | B21: =COUNTIFS('Active Work Orders'!C$4:C$251,"Misc.",'Active Work Orders'!F$4:F$251,">="&(TODAY()-30)) -> 5
A22: Climate/AC | B22: =COUNTIFS('Active Work Orders'!C$4:C$251,"Climate/AC",'Active Work Orders'!F$4:F$251,">="&(TODAY()-30)) -> 5
A23: Electrical | B23: =COUNTIFS('Active Work Orders'!C$4:C$251,"Electrical",'Active Work Orders'!F$4:F$251,">="&(TODAY()-30)) -> 4
A24: Technology | B24: =COUNTIFS('Active Work Orders'!C$4:C$251,"Technology",'Active Work Orders'!F$4:F$251,">="&(TODAY()-30)) -> 15
A25: Plumbing | B25: =COUNTIFS('Active Work Orders'!C$4:C$251,"Plumbing",'Active Work Orders'!F$4:F$251,">="&(TODAY()-30)) -> 15
A26: Walls | B26: =COUNTIFS('Active Work Orders'!C$4:C$251,"Walls",'Active Work Orders'!F$4:F$251,">="&(TODAY()-30)) -> 18
A27: Ceiling | B27: =COUNTIFS('Active Work Orders'!C$4:C$251,"Ceiling",'Active Work Orders'!F$4:F$251,">="&(TODAY()-30)) -> 3
A28: Floors | B28: =COUNTIFS('Active Work Orders'!C$4:C$251,"Floors",'Active Work Orders'!F$4:F$251,">="&(TODAY()-30)) -> 15
A29: Doors | B29: =COUNTIFS('Active Work Orders'!C$4:C$251,"Doors",'Active Work Orders'!F$4:F$251,">="&(TODAY()-30)) -> 13
A30: Safety | B30: =COUNTIFS('Active Work Orders'!C$4:C$251,"Safety",'Active Work Orders'!F$4:F$251,">="&(TODAY()-30)) -> 4

Sheet Active Work Orders
A1: Active Work Orders
A2: Track guest- or staff-reported issues that need immediate attention and follow-up.
A3: Ticket ID | B3: Room/Location | C3: Issue Type | D3: Issue Description | E3: Priority | F3: Date Reported | G3: Status
A4: WO-001 | B4: 213 | C4: Plumbing | D4: Flushmate toilet system leaking full replacement needed. | E4: Critical | F4: 46216.523 | G4: Completed
A5: WO-002 | B5: 313 | C5: Plumbing | D5: Flushmate toilet system leaking full replacement needed. | E5: Critical | F5: 46216.577 | G5: Completed
A6: WO-003 | B6: Other | C6: Misc. | D6: One of the belts on the vacuum for housekeeping broke needs to be replaced | E6: Medium | F6: 46218.396 | G6: Completed
A7: WO-005 | B7: 210 | C7: Floors | D7: Doorstop is broken or off. | E7: Low | F7: 46220 | G7: Completed
A8: WO-009 | B8: 219 | C8: Ceiling | D8: Water from 319s plumbing issue is leaking from the ceiling down onto everything. | E8: Medium | F8: 46220.604 | G8: Completed
A9: WO-011 | B9: 121 | C9: Technology | D9: TV volume is not working. | E9: Low | F9: 46222.381 | G9: Completed
A10: WO-012 | B10: 419 | C10: Misc. | D10: There seems to be an unusual amount of bugs in the room. | E10: Critical | F10: 46222.39 | G10: Completed
A11: WO-013 | B11: 215 | C11: Electrical | D11: Refrigerator not working properly | E11: High | F11: 46222.462 | G11: Completed
A12: WO-014 | B12: 107 | C12: Floors | D12: Carpet needs to be Shampooed | E12: High | F12: 46222.473 | G12: Completed
A13: WO-015 | B13: 303 | C13: Doors | D13: The shower door stopped needs to be adjusted | E13: Low | F13: 46222.517 | G13: Completed
A14: WO-017 | B14: 310 | C14: Floors | D14: Condensation from the a c is soaking the floor | E14: Critical | F14: 46222.596 | G14: Completed
A15: =IF(G15<>"","WO-"&TEXT(ROW()-3,"000"),"") -> WO-012 | B15: 205 | C15: Plumbing | D15: lever to turn on shower isn't working. | E15: High | F15: 46223.443 | G15: Completed
A16: =IF(G16<>"","WO-"&TEXT(ROW()-3,"000"),"") -> WO-013 | B16: 217 | C16: Plumbing | D16: lever to turn on shower isn't working. | E16: High | F16: 46223.457 | G16: Completed
A17: =IF(G17<>"","WO-"&TEXT(ROW()-3,"000"),"") -> WO-014 | B17: 411 | C17: Doors | D17: battery dead door will not open | E17: Critical | F17: 46223.403 | G17: Completed
A18: =IF(G18<>"","WO-"&TEXT(ROW()-3,"000"),"") -> WO-015 | B18: 319 | C18: Floors | D18: room smells, fishy smell. Ozone machine and shampoo carpet. | E18: High | F18: 46223.482 | G18: Completed
A19: =IF(G19<>"","WO-"&TEXT(ROW()-3,"000"),"") -> WO-016 | B19: 208 | C19: Plumbing | D19: toilet is making a weird sound. | E19: Medium | F19: 46223.549 | G19: Completed
A20: =IF(G20<>"","WO-"&TEXT(ROW()-3,"000"),"") -> WO-017 | B20: 211 | C20: Misc. | D20: Bugs in the room guest moved. | E20: Critical | F20: 46224.313 | G20: Completed
A21: =IF(G21<>"","WO-"&TEXT(ROW()-3,"000"),"") -> WO-018 | B21: 317 | C21: Technology | D21: TV is not working properly. | E21: Medium | F21: 46224.435 | G21: Completed
A22: =IF(G22<>"","WO-"&TEXT(ROW()-3,"000"),"") -> WO-019 | B22: 211 | C22: Floors | D22: Stains on floor, shampoo needed. | E22: Medium | F22: 46224.485 | G22: Completed
A23: =IF(G23<>"","WO-"&TEXT(ROW()-3,"000"),"") -> WO-020 | B23: 410 | C23: Walls | D23: Curtain needs to be reattached/adjusted. | E23: Low | F23: 46224.538 | G23: Completed
A24: =IF(G24<>"","WO-"&TEXT(ROW()-3,"000"),"") -> WO-021 | B24: 101 | C24: Walls | D24: Curtain needs to be reattached/adjusted. | E24: Low | F24: 46226.378 | G24: Completed
A25: =IF(G25<>"","WO-"&TEXT(ROW()-3,"000"),"") -> WO-022 | B25: 107 | C25: Walls | D25: Curtain needs to be reattached/adjusted. | E25: Low | F25: 46226.415 | G25: Completed
A26: =IF(G26<>"","WO-"&TEXT(ROW()-3,"000"),"") -> WO-023 | B26: 410 | C26: Walls | D26: Curtain needs to be reattached/adjusted. | E26: Low | F26: 46226.457 | G26: Completed
... A28: =IF(G28<>"","WO-"&TEXT(ROW()-3,"000"),"") -> WO-025 | B28: 215 | C28: Climate/AC | D28: Noise/Crickets in the AC. | E28: Medium | F28: 46226.531 | G28: Completed
A29: =IF(G29<>"","WO-"&TEXT(ROW()-3,"000"),"") -> WO-026 | B29: Other | C29: Plumbing | D29: Employee toilet needs to be repaired. | E29: Critical | F29: 46227.392 | G29: Completed
A30: =IF(G30<>"","WO-"&TEXT(ROW()-3,"000"),"") -> WO-027 | B30: 211 | C30: Walls | D30: Reattach the bodywash holder. | E30: Low | F30: 46227.447 | G30: Completed
A31: =IF(G31<>"","WO-"&TEXT(ROW()-3,"000"),"") -> WO-028 | B31: 310 | C31: Floors | D31: Water from AC needed to be shampooed up. | E31: Low | F31: 46227.51 | G31: Completed
A32: =IF(G32<>"","WO-"&TEXT(ROW()-3,"000"),"") -> WO-029 | B32: 319 | C32: Floors | D32: Soda spilled carpet needs shampooed | E32: Medium | F32: 46227.645 | G32: Completed
A33: =IF(G33<>"","WO-"&TEXT(ROW()-3,"000"),"") -> WO-030 | B33: 211 | C33: Technology | D33: Tv data cable replaced to fix TV not turning off. | E33: High | F33: 46228.427 | G33: Completed
A34: =IF(G34<>"","WO-"&TEXT(ROW()-3,"000"),"") -> WO-031 | B34: 201 | C34: Technology | D34: Tv data cable replaced to fix TV not turning off. | E34: High | F34: 46228.437 | G34: Completed
A35: =IF(G35<>"","WO-"&TEXT(ROW()-3,"000"),"") -> WO-032 | B35: 203 | C35: Technology | D35: Tv data cable replaced to fix TV not turning off. | E35: High | F35: 46228.455 | G35: Completed
A36: =IF(G36<>"","WO-"&TEXT(ROW()-3,"000"),"") -> WO-033 | B36: 410 | C36: Technology | D36: Tv data cable replaced to fix TV not turning off. | E36: High | F36: 46228.478 | G36: Completed
A37: =IF(G37<>"","WO-"&TEXT(ROW()-3,"000"),"") -> WO-034 | B37: 310 | C37: Technology | D37: Tv data cable replaced to fix TV not turning off. | E37: High | F37: 46228.5 | G37: Completed
A38: =IF(G38<>"","WO-"&TEXT(ROW()-3,"000"),"") -> WO-035 | B38: 315 | C38: Technology | D38: Tv data cable replaced to fix TV not turning off. | E38: High | F38: 46228.516 | G38: Completed
A39: =IF(G39<>"","WO-"&TEXT(ROW()-3,"000"),"") -> WO-036 | B39: 413 | C39: Doors | D39: Dead battery door locked out. | E39: Critical | F39: 46228.535 | G39: Completed
A40: =IF(G40<>"","WO-"&TEXT(ROW()-3,"000"),"") -> WO-037 | B40: 101 | C40: Walls | D40: Curtain needs to be reattached/adjusted. | E40: Low | F40: 46228.544 | G40: Completed
A41: =IF(G41<>"","WO-"&TEXT(ROW()-3,"000"),"") -> WO-038 | B41: 219 | C41: Ceiling | D41: Water leaking from ceiling. | E41: Critical | F41: 46228.601 | G41: Completed
...

Sheet Room Inspections
A1: Detailed Room Inspections - Marriott Fairfield
A2: Track room inspections, PM intervals, and follow-up status with a 30-day maintenance cycle.
A3: Date | B3: Room/Space | C3: Inspection Status | D3: HVAC | E3: Plumbing | F3: Electrical | G3: Walls/Floors | H3: Notes | I3: Priority | J3: Performed By | K3: Last PM Date | L3: Next Due Date | M3: Days Remaining | N3: PM Status
A4: 46220 | B4: 210 | C4: Follow-Up | D4: OK | E4: OK | F4: Replace | G4: Repair | H4: Outlet needs to be replaced.Floor needs to be touched up in the bathroom.Walls and trim need to be repaired | I4: High | J4: Pablo | K4: 46220 | L4: =IF(K4="","",K4+30) -> 46250 | M4: =IF(L4="","",L4-TODAY()) -> 16 | N4: =IF(M4="","",IF(M4<0,"Overdue",IF(M4<=7,"Due Soon","Current"))) -> Current
A5: 46223 | B5: 408 | C5: Pass | D5: OK | E5: OK | F5: OK | G5: OK | H5: Asthetic fix, cable management under desk. | I5: Low | J5: Pablo | K5: 46223 | L5: =IF(K5="","",K5+30) -> 46253 | M5: =IF(L5="","",L5-TODAY()) -> 19 | N5: =IF(M5="","",IF(M5<0,"Overdue",IF(M5<=7,"Due Soon","Current"))) -> Current
A6: 46223 | B6: 101 | C6: Follow-Up | D6: OK | E6: Replace | F6: OK | G6: Repair | H6: Handheld shower head is leaking needs to be replaced , and the silicone needs to be redone on the top of the shower | I6: Medium | J6: Pablo | K6: 46223 | L6: =IF(K6="","",K6+30) -> 46253 | M6: =IF(L6="","",L6-TODAY()) -> 19 | N6: =IF(M6="","",IF(M6<0,"Overdue",IF(M6<=7,"Due Soon","Current"))) -> Current
A7: 46224 | B7: 211 | C7: Pass | D7: OK | E7: OK | F7: OK | G7: OK | H7: Nothing significant needs to be repaired or replaced. | I7: Low | J7: Pablo | K7: 46224 | L7: =IF(K7="","",K7+30) -> 46254 | M7: =IF(L7="","",L7-TODAY()) -> 20 | N7: =IF(M7="","",IF(M7<0,"Overdue",IF(M7<=7,"Due Soon","Current"))) -> Current
A8: 46224 | B8: 308 | C8: Pass | D8: OK | E8: OK | F8: OK | G8: OK | H8: Nothing significant needs to be repaired or replaced. | I8: Low | J8: Pablo | K8: 46224 | L8: =IF(K8="","",K8+30) -> 46254 | M8: =IF(L8="","",L8-TODAY()) -> 20 | N8: =IF(M8="","",IF(M8<0,"Overdue",IF(M8<=7,"Due Soon","Current"))) -> Current
A9: 46226 | B9: 107 | C9: Pass | D9: OK | E9: OK | F9: OK | G9: OK | H9: Nothing significant needs to be repaired or replaced. | I9: Low | J9: Pablo | K9: 46226 | L9: =IF(K9="","",K9+30) -> 46256 | M9: =IF(L9="","",L9-TODAY()) -> 22 | N9: =IF(M9="","",IF(M9<0,"Overdue",IF(M9<=7,"Due Soon","Current"))) -> Current
A10: 46226 | B10: 102 | C10: Follow-Up | D10: Repair | E10: OK | F10: OK | G10: Repair | H10: Wallpaper seams concealed better, clean and tab AC. | I10: Medium | J10: Pablo | K10: 46226 | L10: =IF(K10="","",K10+30) -> 46256 | M10: =IF(L10="","",L10-TODAY()) -> 22 | N10: =IF(M10="","",IF(M10<0,"Overdue",IF(M10<=7,"Due Soon","Current"))) -> Current
A11: 46226 | B11: 203 | C11: Follow-Up | D11: Repair | E11: Repair | F11: OK | G11: OK | H11: Touch up caulking in bathroom, clean and tab AC. | I11: Medium | J11: Pablo | K11: 46226 | L11: =IF(K11="","",K11+30) -> 46256 | M11: =IF(L11="","",L11-TODAY()) -> 22 | N11: =IF(M11="","",IF(M11<0,"Overdue",IF(M11<=7,"Due Soon","Current"))) -> Current
A12: 46226 | B12: 215 | C12: Follow-Up | D12: Repair | E12: OK | F12: OK | G12: OK | H12: Ac needs to be cleaned and tabbed. | I12: Low | J12: Pablo | K12: 46226 | L12: =IF(K12="","",K12+30) -> 46256 | M12: =IF(L12="","",L12-TODAY()) -> 22 | N12: =IF(M12="","",IF(M12<0,"Overdue",IF(M12<=7,"Due Soon","Current"))) -> Current
A13: 46226 | B13: 307 | C13: Pass | D13: OK | E13: OK | F13: OK | G13: OK | H13: Nothing significant needs to be repaired or replaced. | I13: Low | J13: Pablo | K13: 46226 | L13: =IF(K13="","",K13+30) -> 46256 | M13: =IF(L13="","",L13-TODAY()) -> 22 | N13: =IF(M13="","",IF(M13<0,"Overdue",IF(M13<=7,"Due Soon","Current"))) -> Current
A14: 46226 | B14: 319 | C14: Follow-Up | D14: Repair | E14: Repair | F14: OK | G14: OK | H14: Readjust toilet actuator(Active WO-010), clean and tab AC. | I14: Medium | J14: Pablo | K14: 46226 | L14: =IF(K14="","",K14+30) -> 46256 | M14: =IF(L14="","",L14-TODAY()) -> 22 | N14: =IF(M14="","",IF(M14<0,"Overdue",IF(M14<=7,"Due Soon","Current"))) -> Current
A15: 46226 | B15: 411 | C15: Follow-Up | D15: Repair | E15: OK | F15: OK | G15: OK | H15: Ac needs to be cleaned and tabbed. | I15: Low | J15: Pablo | K15: 46226 | L15: =IF(K15="","",K15+30) -> 46256 | M15: =IF(L15="","",L15-TODAY()) -> 22 | N15: =IF(M15="","",IF(M15<0,"Overdue",IF(M15<=7,"Due Soon","Current"))) -> Current
... A34: 46229 | B34: 206 | C34: Follow-Up | D34: OK | E34: Repair | F34: OK | G34: OK | H34: Multiple spots in bathroom need to be recaulked. | I34: Medium | J34: Pablo | K34: 46229 | L34: =IF(K34="","",K34+30) -> 46259 | M34: =IF(L34="","",L34-TODAY()) -> 25 | N34: =IF(M34="","",IF(M34<0,"Overdue",IF(M34<=7,"Due Soon","Current"))) -> Current
L35: =IF(K35="","",K35+30) | M35: =IF(L35="","",L35-TODAY()) | N35: =IF(M35="","",IF(M35<0,"Overdue",IF(M35<=7,"Due Soon","Current")))
L36: =IF(K36="","",K36+30) | M36: =IF(L36="","",L36-TODAY()) | N36: =IF(M36="","",IF(M36<0,"Overdue",IF(M36<=7,"Due Soon","Current")))
L37: =IF(K37="","",K37+30) | M37: =IF(L37="","",L37-TODAY()) | N37: =IF(M37="","",IF(M37<0,"Overdue",IF(M37<=7,"Due Soon","Current")))
L38: =IF(K38="","",K38+30) | M38: =IF(L38="","",L38-TODAY()) | N38: =IF(M38="","",IF(M38<0,"Overdue",IF(M38<=7,"Due Soon","Current")))
L39: =IF(K39="","",K39+30) | M39: =IF(L39="","",L39-TODAY()) | N39: =IF(M39="","",IF(M39<0,"Overdue",IF(M39<=7,"Due Soon","Current")))
L40: =IF(K40="","",K40+30) | M40: =IF(L40="","",L40-TODAY()) | N40: =IF(M40="","",IF(M40<0,"Overdue",IF(M40<=7,"Due Soon","Current")))
L41: =IF(K41="","",K41+30) | M41: =IF(L41="","",L41-TODAY()) | N41: =IF(M41="","",IF(M41<0,"Overdue",IF(M41<=7,"Due Soon","Current")))
L42: =IF(K42="","",K42+30) | M42: =IF(L42="","",L42-TODAY()) | N42: =IF(M42="","",IF(M42<0,"Overdue",IF(M42<=7,"Due Soon","Current")))
L43: =IF(K43="","",K43+30) | M43: =IF(L43="","",L43-TODAY()) | N43: =IF(M43="","",IF(M43<0,"Overdue",IF(M43<=7,"Due Soon","Current")))
L44: =IF(K44="","",K44+30) | M44: =IF(L44="","",L44-TODAY()) | N44: =IF(M44="","",IF(M44<0,"Overdue",IF(M44<=7,"Due Soon","Current")))
L45: =IF(K45="","",K45+30) | M45: =IF(L45="","",L45-TODAY()) | N45: =IF(M45="","",IF(M45<0,"Overdue",IF(M45<=7,"Due Soon","Current")))
L46: =IF(K46="","",K46+30) | M46: =IF(L46="","",L46-TODAY()) | N46: =IF(M46="","",IF(M46<0,"Overdue",IF(M46<=7,"Due Soon","Current")))
... L250: =IF(K250="","",K250+30) | M250: =IF(L250="","",L250-TODAY()) | N250: =IF(M250="","",IF(M250<0,"Overdue",IF(M250<=7,"Due Soon","Current")))

Sheet Parts Inventory
A1: Parts Inventory
A2: Manage critical spares, reorder triggers, vendors, and storage locations.
A3: Part ID | B3: Category | C3: Part Name | D3: Equipment/Area | E3: Vendor | F3: Unit Cost | G3: On Hand | H3: Min Level | I3: Reorder Qty | J3: Lead Time (Days) | K3: Reorder Status | L3: Critical Item | M3: Storage Location | N3: Notes

Sheet Daily Tasks
A1: Daily Maintenance Tasks
A2: Use this sheet to manage daily building checks, hotel operations walk-throughs, and shift handoffs.
A3: Task ID | B3: Area | C3: Task | D3: Assigned To | E3: Frequency | F3: Due Day/Date | G3: Est. Minutes | H3: Status | I3: Last Completed | J3: Notes
A4: D-001 | B4: Boiler Room | C4: Check boiler pressure, temperature, and leak points | D4: AM Engineer | E4: Daily | F4: Every Day | G4: 20 | H4: Complete | I4: 46219 | J4: Document readings in log book
A5: D-002 | B5: Pool | C5: Verify pool chemistry and equipment alarms | D5: PM Engineer | E5: Daily | F5: Every Day | G5: 15 | H5: Complete | I5: 46218 | J5: Coordinate with front desk on closures
A6: D-003 | B6: Public Areas | C6: Inspect lobby, corridors, and elevators for lighting or trip hazards | D6: Shift Engineer | E6: Daily | F6: Every Day | G6: 25 | H6: Complete | I6: 46218 | J6: Open work order for deficiencies
A7: D-004 | B7: Exterior | C7: Check parking lot, signage, and entry doors | D7: Shift Engineer | E7: Daily | F7: Every Day | G7: 15 | H7: Complete | I7: 46219 | J7: Note weather-related issues

Sheet Weekly Tasks
A1: Weekly Maintenance Tasks
A2: Use this sheet to plan recurring weekly preventive maintenance work.
A3: Task ID | B3: Area | C3: Task | D3: Assigned To | E3: Frequency | F3: Due Day/Date | G3: Est. Minutes | H3: Status | I3: Last Completed | J3: Notes
A4: W-001 | B4: Guest Rooms | C4: Test sample of PTAC units and clean return grilles | D4: HVAC Tech | E4: Weekly | F4: Monday | G4: 90 | H4: Not Started | I4: 46212 | J4: Rotate floors weekly
A5: W-002 | B5: Fire Safety | C5: Test emergency lighting and exit signage | D5: Electrician | E5: Weekly | F5: Tuesday | G5: 60 | H5: Complete | I5: 46218 | J5: Log failures for replacement
A6: W-003 | B6: Water Systems | C6: Flush low-use fixtures and inspect for odor | D6: Plumber | E6: Weekly | F6: Wednesday | G6: 45 | H6: In Progress | I6: 46213 | J6: Focus on out-of-order rooms
A7: W-004 | B7: Exterior | C7: Inspect roof drains, downspouts, and grounds irrigation | D7: Grounds/Maintenance | E7: Weekly | F7: Friday | G7: 75 | H7: Not Started | I7: 46214 | J7: Escalate ponding issues immediately

Sheet Monthly Tasks
A1: Monthly Maintenance Tasks
A2: Use this sheet to track higher-touch preventive maintenance and inventory routines.
A3: Task ID | B3: Area | C3: Task | D3: Assigned To | E3: Frequency | F3: Due Day/Date | G3: Est. Minutes | H3: Status | I3: Last Completed | J3: Notes
A4: M-001 | B4: Life Safety | C4: Inspect fire extinguishers and document seal/pressure status | D4: Chief Engineer | E4: Monthly | F4: 1st Business Day | G4: 75 | H4: Not Started | I4: 46203 | J4: Coordinate with vendor if replacement is needed
A5: M-002 | B5: Guest Rooms | C5: Deep inspection of 10% of rooms with furnishings checklist | D5: Maintenance Supervisor | E5: Monthly | F5: 2nd Week | G5: 180 | H5: In Progress | I5: 46193 | J5: Use room inspection sheet for findings
A6: M-003 | B6: Inventory | C6: Cycle count critical spares and update reorder points | D6: Storeroom Clerk | E6: Monthly | F6: 3rd Week | G6: 120 | H6: Complete | I6: 46205 | J6: Match with purchasing records
A7: M-004 | B7: Mechanical | C7: Lubricate motors, bearings, and door hardware | D7: Shift Engineer | E7: Monthly | F7: Last Week | G7: 150 | H7: Not Started | I7: 46199 | J7: Record used materials

Sheet Lists
A1: Dropdown Lists
A2: Hidden lookup values used by the dashboard and operating sheets.
A3: Inspection Status | B3: System Status | C3: Priority | D3: Task Status | E3: Critical Item
A4: Pass | B4: OK | C4: Low | D4: Not Started | E4: Yes
A5: Follow-Up | B5: Repair | C5: Medium | D5: In Progress | E5: No
A6: Fail | B6: Replace | C6: High | D6: Complete
C7: Critical | D7: Deferred

Sheet Room Inspection PM
A1: Marriott Fairfield Room Inspection / PM
A2: Printable guest-room inspection sheet tailored to Fairfield standards for guest-ready presentation, PM follow-up, and detailed corrective action tracking.
A4: Date | D4: Inspector
A5: Property / Wing | D5: Room / Floor
A6: Room Type | D6: Work Order
A7: Occupancy | D7: Status / Target
A9: Inspection Item | B9: Fairfield Standard | C9: Result | D9: Notes / Deficiencies | E9: Corrective Action
A10: General Room Readiness
A11: Room presentation | B11: Room is clean, odor-free, well-lit, and guest-ready with no visible clutter or trash.
A12: Bedding and mattress | B12: Linens are fresh, dry, tight, and free of stains or tears; mattress, box spring, and headboard are secure and clean.
A13: Casegoods and upholstery | B13: Desk, chair, nightstand, sofa, and other furniture are dust-free, stable, and free of chips, burns, stains, or loose hardware.
A14: Windows and treatments | B14: Windows, sheers, blackout curtains, and blinds open and close smoothly; fabric is clean and undamaged.
A15: Closet and storage | B15: Closet or wardrobe is clean and organized; hangers, luggage rack, and shelves are present and secure.
A16: Brand amenities | B16: Coffee maker, cups, ice bucket, hair dryer, safe, iron, and board are present and functional when equipped in the room type.
A17: HVAC / Climate Control
A18: PTAC or HVAC power | B18: Unit powers on and responds correctly to the thermostat or control settings.
A19: Heating and cooling | B19: Heating and cooling modes produce strong, even airflow and reach set temperature without delay.
A20: Filter and grille | B20: Return grille, filter, and cabinet are clean, secured, and free of heavy dust build-up.
A21: Noise and vibration | B21: Unit runs quietly with no rattles, grinding, odor, or abnormal vibration.
A22: Condensate and leaks | B22: No water intrusion, condensate overflow, or staining is present around the unit.
A23: Electrical / Lighting / Technology
A24: Room lighting | B24: Entry, bedside, desk, vanity, and bath lighting all operate correctly with working switches or dimmers.
A25: Outlets and USB ports | B25: All outlets, USB ports, and charging stations energize properly and are securely mounted.
A26: GFCI protection | B26: Bathroom and vanity GFCI outlets trip and reset properly; covers and faceplates are intact.
A27: TV and remote | B27: Television powers on, channels or streaming input work, and the remote operates correctly.
A28: Telephone and connectivity | B28: Room phone, data port, or posted Wi-Fi information is present and usable when applicable.
A29: Cords and plugs | B29: Power cords, plugs, and lamp wiring are undamaged, secured, and not creating a hazard.
A30: Plumbing / Bathroom
A31: Sink faucet and drain | B31: Hot and cold water operate correctly, pressure is acceptable, and the sink drains without leaking or backing up.
A32: Toilet operation | B32: Toilet flushes, refills, and seats properly with no rocking, staining, or hidden leaks.
A33: Tub or shower | B33: Tub, shower, head, curtain or door, grout, caulk, and drain are clean, intact, and leak-free.
A34: Vanity and mirror | B34: Countertop, backsplash, mirror, sink basin, and vanity surfaces are clean and damage-free.
A35: Exhaust fan | B35: Bathroom fan vents properly and is free of excessive dust, noise, or damage.
A36: Water temperature | B36: Water temperature is consistent and acceptable at the sink and shower.
A37: Plumbing leaks | B37: No visible leaks are present under the sink, around the toilet, or at wall penetrations.
A38: Walls / Ceiling / Trim
A39: Walls and paint | B39: Walls, wallpaper, and paint are free of holes, stains, peeling, scuffs, and visible patching issues.
A40: Ceiling and vents | B40: Ceiling, sprinkler escutcheons, diffusers, and vents are clean with no water marks or cracks.
A41: Trim and caulk | B41: Baseboards, corner beads, trim, and caulk lines are intact, sealed, and finished cleanly.
A42: Artwork and mirrors | B42: Artwork, mirrors, and décor are straight, secure, and free of chips, cracks, or fading.
...

Sheet FLUSHMATE SNs
A2: 30075 Research Dr., New Hudson, MI 48165 | G2: Site Information
A3: Fax: | G3: Contact: Pablo Chakone
A4: Contact: | G4: Company: Fairfield Inn & Suites
G5: Address: 203 Outlet Dr., Hillsboro, TX 76645
G6: Phone: (254) 582-8804
G7: Email: fairfield.maint.203@gmail.com
A8: Flushmate Serial Number Log
B9: Model # | C9: Serial # | E9: Install Date | H9: Model # | I9: Serial # | K9: Install Date
A10: 101 | C10: - | D10: - | E10: / / | G10: 307 | I10: - | J10: - | K10: / /
A11: 102 | C11: - | D11: - | E11: / / | G11: 308 | I11: - | J11: - | K11: / /
A12: 103 | C12: - | D12: - | E12: / / | G12: 309 | I12: - | J12: - | K12: / /
A13: 104 | C13: - | D13: - | E13: / / | G13: 310 | I13: - | J13: - | K13: / /
A14: 105 | C14: - | D14: - | E14: / / | G14: 311 | I14: - | J14: - | K14: / /
A15: 106 | C15: - | D15: - | E15: / / | G15: 313 | I15: - | J15: - | K15: / /
A16: 107 | C16: - | D16: - | E16: / / | G16: 314 | I16: - | J16: - | K16: / /
A17: 121 | C17: - | D17: - | E17: / / | G17: 315 | I17: - | J17: - | K17: / /
A18: 201 | C18: - | D18: - | E18: / / | G18: 316 | I18: - | J18: - | K18: / /
A19: 202 | C19: - | D19: - | E19: / / | G19: 317 | I19: - | J19: - | K19: / /
A20: 203 | C20: - | D20: - | E20: / / | G20: 318 | I20: - | J20: - | K20: / /
A21: 204 | C21: - | D21: - | E21: / / | G21: 319 | I21: - | J21: - | K21: / /
... A41: 305 | C41: - | D41: - | E41: / / | G41: 421 | I41: - | J41: - | K41: / /
A42: 306 | C42: - | D42: - | E42: / / | I42: - | J42: - | K42: / /
